Workbook

Sheet LEEME
A1: Trazabilidad de Encomiendas — Base del proyecto (MVP demo)
A2: Cooperativa Unión Transportes Cariamanga · Para: Abel · Uso interno · Documento vivo
A4: Qué es esto
A5: Todo lo necesario para construir la demo en un solo libro: stack, decisiones, base de datos, estados, permisos, pantallas, API, mensajes, plan, guion y riesgos. Complementa la spec v5 y la v5.1; donde se contradicen, mandan las enmiendas más recientes (hoja Decisiones). Archivos hermanos: 001_init_mvp.sql y seed.sql.
A7: Avance (se calcula solo desde la hoja Plan)
A8: Etapa | B8: Tareas | C8: Hechas | D8: %
A9: E0 — Reglas del dominio | B9: =COUNTIF(Plan!$B$4:$B$39,"E0") -> 7 | C9: =COUNTIFS(Plan!$B$4:$B$39,"E0",Plan!$F$4:$F$39,"Hecho") -> 7 | D9: =IF(B9=0,0,C9/B9) -> 1
A10: E1 — Base de datos | B10: =COUNTIF(Plan!$B$4:$B$39,"E1") -> 7 | C10: =COUNTIFS(Plan!$B$4:$B$39,"E1",Plan!$F$4:$F$39,"Hecho") -> 5 | D10: =IF(B10=0,0,C10/B10) -> 0.71428571
A11: E2 — Encomienda a escaneo | B11: =COUNTIF(Plan!$B$4:$B$39,"E2") -> 7 | C11: =COUNTIFS(Plan!$B$4:$B$39,"E2",Plan!$F$4:$F$39,"Hecho") -> 6 | D11: =IF(B11=0,0,C11/B11) -> 0.85714286
A12: E3 — Salida, recepción, redespacho | B12: =COUNTIF(Plan!$B$4:$B$39,"E3") -> 6 | C12: =COUNTIFS(Plan!$B$4:$B$39,"E3",Plan!$F$4:$F$39,"Hecho") -> 5 | D12: =IF(B12=0,0,C12/B12) -> 0.83333333
A13: E4 — Entrega, mensajes, panel | B13: =COUNTIF(Plan!$B$4:$B$39,"E4") -> 8 | C13: =COUNTIFS(Plan!$B$4:$B$39,"E4",Plan!$F$4:$F$39,"Hecho") -> 5 | D13: =IF(B13=0,0,C13/B13) -> 0.625
A14: Despliegue | B14: =COUNTIF(Plan!$B$4:$B$39,"Despliegue") -> 1 | C14: =COUNTIFS(Plan!$B$4:$B$39,"Despliegue",Plan!$F$4:$F$39,"Hecho") -> 0 | D14: =IF(B14=0,0,C14/B14) -> 0
A15: TOTAL | B15: =SUM(B9:B14) -> 36 | C15: =SUM(C9:C14) -> 28 | D15: =IF(B15=0,0,C15/B15) -> 0.77777778
A17: Criterios de aceptación del MVP
A18: Entran en el MVP | B18: =COUNTIF(Aceptación!$E$3:$E$24,"<>Fuera del MVP") -> 18
A19: Cumplidos | B19: =COUNTIF(Aceptación!$E$3:$E$24,"Cumplido") -> 15
A21: Hojas
A22: Stack | B22: Qué tecnologías y por qué
A23: Decisiones | B23: Enmiendas nuevas E-11 a E-22
A24: Necesito de ti | B24: Lo que debes darme (pendientes tuyos)
A25: Carpetas | B25: Estructura del código
A26: Tablas BD | B26: 25 tablas, triggers y vista
A27: Estados | B27: Máquina de estados del bulto, encomienda y redespacho
A28: Roles y permisos | B28: Quién puede qué
A29: Reglas e invariantes | B29: Lo que nunca se rompe
A30: Pantallas | B30: 12 pantallas
A31: API | B31: Endpoints
A32: Mensajes WhatsApp | B32: Avisos con Evolution
A33: Parametros | B33: Configuración y .env
... A38: Bitácora | B38: Historial
A40: Leyenda
A41: Encabezado azul oscuro | B41: títulos de tabla
A42: Fila celeste | B42: sección dentro de una hoja
A43: Listas desplegables | B43: columnas Estado en Plan, Necesito de ti y Aceptación: se cambian a mano

Sheet Stack
A1: Stack recomendado (MVP demo)
A2: Elegí Next.js porque lo propusiste y encaja: una sola aplicación. Lo que no encaja con cPanel/MySQL se cambió y está documentado en la hoja 'Decisiones'.
A3: Capa | B3: Elección | C3: Por qué | D3: Alternativa descartada | E3: Quién lo pone
A4: Aplicación | B4: Next.js (App Router) + React + TypeScript estricto | C4: Un solo proyecto para pantallas Y servidor (API). La v5 pedía Fastify + Vite por separado: son 2 proyectos, 2 despliegues. Para una demo, uno solo es más rápido. | D4: Fastify + React/Vite (como la v5) | E4: Yo escribo
A5: Base de datos | B5: MySQL / MariaDB del cPanel, motor InnoDB, utf8mb4 | C5: Es lo que tienes. Soporta transacciones, SELECT … FOR UPDATE, triggers y vistas, que es todo lo que el diseño necesita. SQL ya probado en MariaDB 10.11. | D5: PostgreSQL (la v5 original) | E5: Tú: acceso. Yo: SQL
A6: Acceso a BD | B6: mysql2 con SQL directo | C6: El diseño depende de transacciones, bloqueos de fila y SQL exacto. Un ORM (Prisma) estorba justo en eso. | D6: Kysely (SQL tipado) | E6: Yo escribo
A7: Validación | B7: Zod | C7: Todo lo que entra a la API se valida con el mismo esquema que usa la pantalla. | D7: — | E7: Yo escribo
A8: Login y sesión | B8: argon2id + cookie HttpOnly + tabla `sesion` | C8: Sin servicios externos. La cookie guarda un token; en BD solo su hash. | D8: Auth.js (más pesado para 4 usuarios) | E8: Yo escribo
A9: Pantallas | B9: Tailwind CSS (+ componentes simples) | C9: Rápido y responsive para celular. Botones grandes y colores fuertes para el escaneo. | D9: shadcn/ui, MUI | E9: Yo escribo
A10: Escáner QR | B10: BarcodeDetector del navegador + respaldo @zxing/browser; campo para escribir el código XXXX-XXXX | C10: Si la cámara falla en la demo, se escribe el código y sigue funcionando. | D10: Lector Bluetooth (entra como teclado; ya funciona con el campo) | E10: Yo escribo
A11: Generar QR y etiquetas | B11: Paquete `qrcode` + CSS @page + window.print() | C11: Imprime desde el navegador (E-10). Sin impresora térmica en la demo. | D11: ESC/POS | E11: Yo escribo
A12: Mensajes WhatsApp | B12: Evolution API (tuyo) detrás de una interfaz `EnviadorMensajes`; adaptador simulado para pruebas | C12: Con la interfaz, cambiar de proveedor es cambiar un archivo. El simulado permite ensayar sin enviar mensajes reales. | D12: WhatsApp Cloud API oficial (Meta) | E12: Tú: Evolution. Yo: adaptador
A13: Envíos en segundo plano | B13: Endpoint /api/cron/mensajes + tarea cron de cPanel cada minuto (curl con clave secreta) | C13: En cPanel no hay un proceso que quede corriendo siempre. El cron es lo fiable. Cola con reintentos. | D13: Worker propio / Redis (NO: fuera de alcance) | E13: Tú: crear el cron. Yo: endpoint
A14: Pruebas | B14: Vitest (reglas del dominio + integración contra MySQL real) · Playwright opcional para el guion completo | C14: Las reglas críticas se prueban sin levantar nada. Las de BD, contra una BD real, no con mocks. | D14: — | E14: Yo escribo
... A18: NO usamos | B18: Redis · microservicios · Service Worker/offline · Prisma · row-level security | C18: Fuera del MVP (E-01, E-08) o no encajan con MySQL/cPanel. | D18: — | E18: —

Sheet Decisiones
A1: Enmiendas nuevas (continúan E-01 a E-10 de la v5.1)
A2: Copiar estas filas a la bitácora de enmiendas_v5.1. Regla: donde esto y la v5 se contradicen, manda esto.
A3: Enmienda | B3: Decisión | C3: Qué cambia respecto a la v5 / v5.1 | D3: Motivo | E3: Estado | F3: Quién decide
A4: E-11 | B4: Base de datos: PostgreSQL → MySQL/MariaDB (cPanel) | C4: Tipos (uuid→CHAR(36), jsonb→JSON, timestamptz→DATETIME(3) en UTC). Los UUID los genera la app. Índices únicos parciales → columna `vigente_key` que escribe la app (NULL = no vigente) + índice único. `bool_and/bool_or` → MIN()/MAX(). Sin RETURNING: el contador de intentos usa LAST_INSERT_ID(intentos+1). Triggers con SIGNAL SQLSTATE '45000'. | D4: Tu stack es cPanel (MySQL/MariaDB). Probé el SQL en MariaDB 10.11: me falló usar columnas generadas con índice único, por eso el cambio a `vigente_key`. Falta probarlo en TU cPanel. | E4: Aceptada (por tu stack) | F4: Abel
A5: E-12 | B5: Aplicación: Fastify + Vite → Next.js full-stack | C5: Un solo proyecto. Las rutas /api reemplazan a Fastify. `domain/` sigue puro e independiente (regla de oro de la v5). | D5: Lo pediste y reduce piezas para una demo. | E5: Propuesta (recomendada) | F5: Abel
A6: E-13 | B6: WhatsApp: adaptador simulado → Evolution API | C6: Se agrega `evolution.ts` implementando `EnviadorMensajes`. El simulado se conserva para pruebas y ensayos. Cambia E-04. | D6: Ya tienes Evolution. Ojo: los mensajes serán REALES; en la demo, solo a números propios. | E6: Aceptada | F6: Abel
A7: E-14 | B7: Avisos de avance al destinatario (tu 'dónde va su pedido') | C7: La v5 limitaba a 3 mensajes y NO avisaba en paradas intermedias. Se propone: registro · en camino · llegó a agencia intermedia · disponible + código. Parámetro `mensajes.max_por_encomienda` de 3 → 5. Los textos dicen 'última información registrada', nunca ubicación en vivo. | D7: Es lo que pediste. Pero la v5 lo había acotado por decisión de Cheche (costo y ruido): necesita su visto bueno antes de producción. En la demo no hay costo por mensaje con Evolution. | E7: Propuesta — confirmar con Cheche | F7: Cheche
A8: E-15 | B8: Envío de mensajes por cron, no por worker permanente | C8: `notificacion` se mantiene como cola. Un cron de cPanel llama /api/cron/mensajes cada minuto. Se mantiene dedupe_key y reintentos con espera creciente. | D8: cPanel no mantiene procesos corriendo. Retraso máximo ~1 min, aceptable. | E8: Aceptada | F8: Abel
A9: E-16 | B9: Cotización: detalle por bulto | C9: `cotizacion.regla_id` → `cotizacion.detalle` (JSON con la regla aplicada a cada bulto). Se quitan `regla_id`, `foto`. | D9: Error de la v5: se cotiza por bulto pero guardaba una sola regla. (Sigue pendiente confirmar si la cooperativa cobra por bulto o por encomienda.) | E9: Aceptada | F9: Abel
A10: E-17 | B10: Tabla `sesion` nueva | C10: Guarda el hash del token de la cookie, expiración y último uso (cierre por inactividad). | D10: La v5 pedía sesiones pero no definía dónde se guardan. | E10: Aceptada | F10: Abel
A11: E-18 | B11: Zona horaria | C11: Todo se guarda en UTC. Las pantallas muestran America/Guayaquil (UTC-5). | D11: Los servidores de cPanel suelen estar en otra zona; evita que 'vencido' y las horas salgan mal. | E11: Aceptada | F11: Abel
A12: E-19 | B12: Entrega: el codigo se verifica DENTRO de la misma peticion de entrega | C12: Se elimina el endpoint /entregas/verificar-codigo. La v5 devolvia un codigoId que el cliente reenviaba: un cliente malicioso podia reenviar un id sin haber acertado el codigo. Ahora POST /api/entregas recibe el codigo, lo verifica (intento contado de forma atomica, fuera de la transaccion) y entrega. | D12: Cierra un hueco de seguridad de la v5. | E12: Aceptada (implementada) | F12: Abel
A13: E-20 | B13: Entrega parcial: el supervisor se identifica en el momento | C13: El formulario pide correo y contrasena del supervisor (verificados en el servidor); debe ser otra persona distinta de quien entrega. Reemplaza el `supervisorId` que la v5 pasaba sin verificar. | D13: Nadie aprueba 'en nombre de' otro. | E13: Aceptada (implementada) | F13: Abel
A14: E-21 | B14: Incidencias sobrante / descarga incorrecta bloquean la salida hasta resolverse | C14: Se mantiene la regla v5 (no excepcionables). Consecuencia en la demo: tras un escaneo ajeno o un intento de bajar un bulto que continua, el supervisor debe RESOLVER la incidencia antes de autorizar. El guion lo incluye. | D14: Es el comportamiento de la v5; se hace explicito en el guion. | E14: Aceptada (implementada) | F14: Abel
A15: E-22 | B15: Modo prueba de mensajes por variables de entorno | C15: MENSAJES_PROVEEDOR y MENSAJES_NUMEROS_PERMITIDOS viven en .env (no en la tabla parametro). Con evolution solo se envia a los numeros permitidos; el codigo de retiro se redacta tras enviarse. | D15: Evita enviar mensajes reales por accidente. | E15: Aceptada (implementada) | F15: Abel

Sheet Necesito de ti
A1: Lo que necesito de ti
A2: Cámbiale el estado a 'Entregado' conforme lo vayas teniendo. Nunca me pases contraseñas ni API keys por el chat: van en el archivo .env de tu equipo.
A3: # | B3: Qué necesito | C3: Para qué | D3: Cómo dármelo | E3: Cuándo | F3: Estado
A4: 1 | B4: Versión de MySQL/MariaDB del cPanel | C4: Ajusto el SQL a tu versión exacta | D4: En phpMyAdmin ejecuta: SELECT VERSION(); y me pasas el resultado | E4: Bloquea E1 | F4: Pendiente
A5: 2 | B5: Prueba de TRIGGERS en tu cPanel | C5: Los eventos inmutables dependen de triggers. En hosting compartido a veces están bloqueados | D5: En phpMyAdmin → SQL, pega: CREATE TABLE z(a INT); CREATE TRIGGER z_t BEFORE UPDATE ON z FOR EACH ROW SIGNAL SQLSTATE '45000' SET MESSAGE_TEXT='no'; -- si da error 1419 o 'SUPER privilege', avísame. Luego: DROP TABLE z; | E5: Bloquea E1 (crítico) | F5: Pendiente
A6: 3 | B6: Datos de conexión a la BD: host, puerto, nombre de la BD, usuario | C6: Para armar el .env | D6: NO me pases la contraseña por el chat: va solo en tu archivo .env local. Dime si el host es 'localhost' (app en el mismo cPanel) o remoto. | E6: Bloquea E1 | F6: Pendiente
A7: 4 | B7: ¿Acceso remoto a MySQL habilitado? (cPanel → 'Remote MySQL') | C7: Si la app corre en tu laptop, la BD debe aceptar tu IP | D7: Agrega tu IP pública (no uses el comodín %). Dime si lo permite tu hosting | E7: Solo si opción B | F7: Pendiente
A8: 5 | B8: ¿Tu cPanel tiene 'Setup Node.js App'? ¿Qué versiones de Node? | C8: Necesito Node 20 o superior para correr Next.js ahí | D8: Captura o texto de esa pantalla. Si no existe, la app corre en tu laptop (opción B) o en un VPS | E8: Bloquea el despliegue (no E0) | F8: Pendiente
A9: 6 | B9: Dónde se hará la demo en vivo | C9: Define opción A / B / C del Stack | D9: Laptop, cPanel o VPS; y si hay un dominio/subdominio con HTTPS (la cámara lo exige) | E9: Antes de E4 | F9: Pendiente
A10: 7 | B10: Evolution API: URL base, nombre de la instancia y versión (v1 o v2) | C10: El formato de la petición de envío cambia entre versiones | D10: URL e instancia sí me los puedes pasar. La API key va solo en el .env, no en el chat | E10: Bloquea E4 | F10: Pendiente
A11: 8 | B11: ¿La instancia de Evolution ya tiene el WhatsApp conectado (QR escaneado)? | C11: Sin eso no sale ningún mensaje | D11: Sí / No | E11: Bloquea E4 | F11: Pendiente
A12: 9 | B12: Número(s) de WhatsApp de prueba para recibir los avisos | C12: En la demo los mensajes son reales. Solo debemos enviar a números tuyos o de gente que lo sepa | D12: Formato internacional sin +: 5939XXXXXXXX | E12: Antes de E4 | F12: Pendiente
A13: 10 | B13: Confirmar: ¿el número de Evolution es dedicado? | C13: Evolution usa WhatsApp Web (no oficial): si se abusa, pueden bloquear el número. No uses el personal principal | D13: Sí/No. Recomendado: línea aparte | E13: Antes de E4 | F13: Pendiente
A14: 11 | B14: Visto bueno de Cheche a los avisos de avance (E-14) | C14: La v5 los limitaba. Para la demo avanzo con el modo ampliado, pero debe quedar decidido | D14: Sí / No / Solo registro y disponible | E14: Antes de producción | F14: Pendiente
A15: 12 | B15: ¿Los avisos van solo al destinatario o también al remitente? | C15: Es el bloqueante 7 de la v5 | D15: Decisión de Cheche. En la demo: solo destinatario | E15: Antes de producción | F15: Pendiente
... A19: 16 | B19: Datos reales de la cooperativa | C19: NINGUNO. La demo usa datos ficticios (tarifas, rutas, personas) | D19: — | E19: No se necesita | F19: No aplica

Sheet Carpetas
A1: Estructura del proyecto
A2: Ruta | B2: Qué contiene | C2: Regla / nota
A3: / | B3: Raíz del proyecto Next.js | C3: package.json, tsconfig.json (strict), next.config, vitest.config, .env.example
A4: src/domain/ | B4: REGLAS PURAS: estados.ts, escaneo.ts, salida.ts, tarifa.ts, codigos.ts | C4: Regla de oro: NO importa BD, HTTP ni Next. Se prueba sin levantar nada
A5: src/server/db/ | B5: Pool mysql2, helper de transacciones, consultas | C5: Una transacción por operación; SELECT … FOR UPDATE sobre la fila que cambia
A6: src/server/services/ | B6: escanear, manifiesto, salida, recepcion, redespacho, entrega, encomienda, cotizacion | C6: Aquí se une el dominio puro con la BD
A7: src/server/auth/ | B7: Login, sesión, cookies, permisos (exigirRol), permisos por agencia | C7: argon2id; cookie HttpOnly
A8: src/server/mensajes/ | B8: interfaz EnviadorMensajes, evolution.ts, simulado.ts, plantillas.ts, cola.ts | C8: Cambiar de proveedor = cambiar un archivo
A9: src/server/comun/ | B9: ErrorNegocio, param() (lee la tabla parametro), reloj, uuid | C9: Son las funciones auxiliares que la v5 dejó sin definir
A10: src/shared/ | B10: Tipos, esquemas Zod, matriz de permisos | C10: Lo comparten pantallas y servidor
A11: src/app/(auth)/login/ | B11: Pantalla 1: Login
A12: src/app/(app)/… | B12: Pantallas 2–9 (ver hoja Pantallas) | C12: Layout con menú por rol
A13: src/app/api/… | B13: Endpoints (ver hoja API) | C13: Route handlers; validan con Zod y llaman a services
A14: src/app/q/[token]/ | B14: Página pública del QR | C14: Responde IGUAL con token válido o inválido
A15: db/ | B15: 001_init_mvp.sql y seed.sql | C15: Ya entregados y probados en MariaDB 10.11
A16: scripts/ | B16: seed-usuarios.ts (pone el hash argon2), reset-demo.ts (deja la demo como nueva) | C16: reset-demo permite repetir el guion cuantas veces haga falta
A17: tests/unit/ | B17: Pruebas del dominio (v5 §10.1, sin offline) | C17: Primero en escribirse
A18: tests/integration/ | B18: Pruebas contra MySQL real: concurrencia, idempotencia, trigger, intentos, vigencia | C18: Sin mocks
A19: tests/e2e/ | B19: El guion de la demo completo | C19: Es la prueba principal
A20: docs/ | B20: trazabilidad_encomiendas_v5, enmiendas_v5.1, este Excel | C20: Documento vivo
A21: .env.example | B21: DATABASE_*, SESSION_SECRET, RETIRO_HMAC_SECRET, EVOLUTION_*, CRON_SECRET, MENSAJES_PROVEEDOR | C21: El .env real NUNCA va al repositorio

Sheet Tablas BD
A1: Base de datos (25 tablas) — archivo: 001_init_mvp.sql
A2: Esta hoja y el .sql salen de la misma definición, así que no se contradicen. Quitado respecto a la v5 por E-01/E-10: pin_hash, seq_cliente, campos offline, ajuste_cotizacion, params_cifrados, sustituto_de, foto.
A3: Tabla | B3: Columna | C3: Tipo y restricciones (MySQL/MariaDB) | D3: Nota
A4: agencia — Agencias de la cooperativa (Quito, Loja, Zumba en la demo)
A5: agencia | B5: id | C5: CHAR(36) NOT NULL | D5: UUID generado por la app (crypto.randomUUID)
A6: agencia | B6: nombre | C6: VARCHAR(80) NOT NULL
A7: agencia | B7: ciudad | C7: VARCHAR(80) NULL
A8: agencia | B8: activa | C8: TINYINT(1) NOT NULL DEFAULT 1
A9: agencia | B9: (restricción / índice) | C9: PRIMARY KEY (id)
A10: usuario — Cuentas individuales. Se desactivan, no se borran
A11: usuario | B11: id | C11: CHAR(36) NOT NULL | D11: UUID generado por la app (crypto.randomUUID)
A12: usuario | B12: nombre | C12: VARCHAR(100) NOT NULL
A13: usuario | B13: email | C13: VARCHAR(120) NOT NULL
A14: usuario | B14: password_hash | C14: VARCHAR(255) NOT NULL | D14: argon2id; lo escribe el script de seed
A15: usuario | B15: activo | C15: TINYINT(1) NOT NULL DEFAULT 1
A16: usuario | B16: creado_at | C16: DATETIME(3) NOT NULL DEFAULT CURRENT_TIMESTAMP(3)
A17: usuario | B17: (restricción / índice) | C17: PRIMARY KEY (id)
A18: usuario | B18: (restricción / índice) | C18: UNIQUE KEY uq_usuario_email (email)
A19: usuario_rol — Qué rol tiene cada usuario y en qué agencia (agencia NULL = todas)
A20: usuario_rol | B20: id | C20: CHAR(36) NOT NULL | D20: UUID generado por la app (crypto.randomUUID)
A21: usuario_rol | B21: usuario_id | C21: CHAR(36) NOT NULL
A22: usuario_rol | B22: rol | C22: ENUM('operador','despachador','ayudante','guardia','responsable_agencia','evaluador','supervisor','gerente','admin') NOT NULL
A23: usuario_rol | B23: agencia_id | C23: CHAR(36) NULL | D23: NULL = todas las agencias
A24: usuario_rol | B24: agencia_key | C24: CHAR(36) NOT NULL DEFAULT 'todas' | D24: Igual a agencia_id, o 'todas' si agencia_id es NULL. La escribe la app; permite un índice único que trate NULL como valor
A25: usuario_rol | B25: (restricción / índice) | C25: PRIMARY KEY (id)
A26: usuario_rol | B26: (restricción / índice) | C26: UNIQUE KEY uq_usuario_rol (usuario_id, rol, agencia_key)
A27: usuario_rol | B27: (restricción / índice) | C27: FOREIGN KEY (usuario_id) REFERENCES usuario(id)
A28: usuario_rol | B28: (restricción / índice) | C28: FOREIGN KEY (agencia_id) REFERENCES agencia(id)
A29: sesion — Sesiones de login (NUEVA: la v5 no la definía). Se guarda el hash del token de la cookie
A30: sesion | B30: id | C30: CHAR(64) NOT NULL | D30: SHA-256 (hex) del token de la cookie
A31: sesion | B31: usuario_id | C31: CHAR(36) NOT NULL
A32: sesion | B32: creado_at | C32: DATETIME(3) NOT NULL DEFAULT CURRENT_TIMESTAMP(3)
A33: sesion | B33: expira_at | C33: DATETIME(3) NOT NULL
A34: sesion | B34: ultimo_uso_at | C34: DATETIME(3) NOT NULL DEFAULT CURRENT_TIMESTAMP(3) | D34: Cierre por inactividad
A35: sesion | B35: (restricción / índice) | C35: PRIMARY KEY (id)
A36: sesion | B36: (restricción / índice) | C36: FOREIGN KEY (usuario_id) REFERENCES usuario(id)
A37: ruta — Rutas
A38: ruta | B38: id | C38: CHAR(36) NOT NULL | D38: UUID generado por la app (crypto.randomUUID)
A39: ruta | B39: nombre | C39: VARCHAR(100) NOT NULL
A40: ruta | B40: (restricción / índice) | C40: PRIMARY KEY (id)
...

Sheet Estados
A1: Máquina de estados (única fuente de verdad: src/domain/estados.ts)
A2: Acción / estado | B2: Desde | C2: Hasta / resultado | D2: Quién | E2: Nota
A3: Transiciones normales del bulto (el servidor las valida; el cliente nunca decide)
A4: cerrar manifiesto | B4: registrado · pendiente_redespacho | C4: pendiente_despacho | D4: Operador (despacho) | E4: Al CERRAR el manifiesto (no al asignarlo). Se fija viaje_actual_id
A5: cargar | B5: pendiente_despacho | C5: cargado | D5: Ayudante (escaneo de carga) | E5: Solo si el bulto SUBE en esa parada
A6: salida real | B6: cargado | C6: en_transito | D6: Supervisor (registra salida) | E6: Solo los que suben en esa parada. Los que continúan ya están en_transito: NO cambian
A7: descargar | B7: en_transito | C7: descargado | D7: Ayudante (escaneo de descarga) | E7: Solo si BAJA en esa parada. Si continúa: alerta, sin cambio
A8: recibir | B8: descargado | C8: recibido_agencia | D8: Operador de la agencia (escanea) | E8: No existe 'recibir todo el lote' sin escanear cada bulto
A9: automático tras recibir | B9: recibido_agencia | C9: disponible_retiro (si es su destino final) · pendiente_redespacho (si no) | D9: Sistema | E9: Crea la tarea de redespacho con plazo
A10: entregar | B10: disponible_retiro | C10: entregado | D10: Operador | E10: Código o documento; parcial con supervisor y motivo
A11: Estados especiales (con permiso, motivo y evento vinculado)
A12: anular | B12: registrado · pendiente_despacho · pendiente_redespacho | C12: anulado | D12: Supervisor | E12: Bloquea toda operación
A13: retener | B13: casi cualquiera antes de entregado | C13: retenido (guarda estado_previo) | D13: Supervisor | E13: Bloquea carga y descarga
A14: liberar | B14: retenido | C14: estado_previo | D14: Supervisor
A15: devuelto | B15: — | C15: devuelto | D15: Fuera del MVP (solo existe el estado)
A16: Resultados de un escaneo
A17: ok | C17: Cambia de estado
A18: repetido | C18: No cambia ni suma | E18: Mismo bulto escaneado otra vez
A19: ya_a_bordo / debia_continuar | C19: No cambia | E19: Bulto que continúa: informativo en carga, alerta roja en descarga
A20: no_esperado (sobrante) | C20: No cambia · abre incidencia 'sobrante' | E20: No pertenece al viaje
A21: descarga_incorrecta | C21: No cambia · abre incidencia | E21: No viene en este viaje. Nunca se cambia el destino en silencio
A22: pasado de parada (G4) | C22: Baja igualmente · incidencia 'pasado_de_parada' + redespacho de retorno | E22: La realidad física manda
A23: bloqueado | C23: No cambia | E23: Anulado, retenido, devuelto o entregado
A24: conflicto_asignacion | C24: No cambia | E24: Cargado en otro viaje activo, o estado incompatible. Gana el primer escaneo
A25: desconocido | C25: Se registra sin bulto | E25: QR que no existe
A26: Estado de la ENCOMIENDA (se calcula con la vista, no se guarda)
A27: entregada | B27: todos los bultos entregados
A28: disponible_retiro | B28: todos los bultos disponibles o ya entregados | E28: Aquí se emite el código y se avisa
A29: parcialmente_disponible | B29: algunos disponibles | E29: NO se avisa 'ya puedes retirar'
A30: en_transito | B30: algún bulto cargado o en tránsito
A31: en_proceso | B31: el resto
A32: Tarea de REDESPACHO (sin estado propio: se deriva)
A33: Pendiente de asignación | B33: bulto pendiente_redespacho y fuera de todo manifiesto borrador
A34: Asignado | B34: figura en un manifiesto borrador (sin cerrar)
A35: Pendiente de carga | B35: bulto en pendiente_despacho (manifiesto cerrado)
A36: Despachado | B36: bulto cargado o en_transito (o posterior) → se llena cerrado_at
A37: Vencido | B37: due_at < ahora y cerrado_at vacío → rojo en el panel (E-07: sin job)

Sheet Roles y permisos
A1: Roles de la demo (4 usuarios, E-03) y qué puede hacer cada uno
A2: En BD se mantienen los 9 roles de la v5. Operador = operador + despachador. Supervisor = supervisor + guardia + responsable_agencia. Reglas extra en el código: nadie aprueba su propia excepción; todo permiso se evalúa contra la agencia; filtro por agencia siempre en el servidor.
A3: Permiso | B3: Operador | C3: Ayudante | D3: Supervisor | E3: Gerente
A4: Registrar encomienda y bultos | B4: ✔
A5: Cotizar (tabla de tarifas) | B5: ✔
A6: Imprimir etiquetas | B6: ✔
A7: Armar / cerrar / modificar manifiesto (con motivo) | B7: ✔
A8: Escanear carga y descarga | B8: ✔ (recepción) | C8: ✔
A9: Contar los bultos que continúan a bordo | C9: ✔
A10: Autorizar salida (como guardia / responsable) | D10: ✔
A11: Registrar salida real | D11: ✔
A12: Autorizar excepción A (con motivo; solicitante ≠ autorizador) | D12: ✔
A13: Recepción en agencia | B13: ✔
A14: Asignar redespacho | B14: ✔ | D14: ✔
A15: Entrega con código o documento | B15: ✔
A16: Entrega parcial (supervisor + motivo) | D16: ✔
A17: Resolver incidencias | D17: ✔
A18: Ver panel de su rol | B18: ✔ | C18: ✔ | D18: ✔ | E18: ✔
A19: Ver mensajes enviados | D19: ✔ | E19: ✔
A20: Exportar CSV de eventos | D20: ✔ | E20: ✔
A21: Escribir en eventos operativos | B21: ✔ | C21: ✔ | D21: ✔ | E21: ✘ solo lectura
A23: Usuarios sembrados: operador@demo.local · ayudante@demo.local · supervisor@demo.local · gerente@demo.local (la contraseña la fijas tú al correr seed-usuarios).

Sheet Reglas e invariantes
A1: Reglas que no se rompen (si una prueba las viola, el build falla)
A2: # | B2: Regla | C2: Cómo se garantiza | D2: Prueba que la verifica | E2: Estado
A3: 1 | B3: La tarifa la decide una tabla versionada, nunca un modelo. Cada cotización guarda la versión usada | C3: Servidor + BD (tarifa_version) | D3: Unitaria de tarifa | E3: Vigente
A4: 2 | B4: Contar N escaneos no autoriza la salida: se concilian bultos únicos y correctos contra el manifiesto | C4: Dominio (salida.ts) | D4: Unitaria de salida | E4: Vigente
A5: 3 | B5: Eventos inmutables; una corrección es un evento nuevo | C5: Triggers en BD | D5: Integración: UPDATE/DELETE fallan | E5: Vigente (correcciones: fuera de MVP)
A6: 4 | B6: Toda transición se valida en el servidor, con bloqueo de fila y versión | C6: Servicios + FOR UPDATE | D6: Integración: concurrencia | E6: Vigente
A7: 5 | B7: Escaneos idempotentes por event_id (UUID del cliente) | C7: PK de evento + captura de error 1062 (clave duplicada) | D7: Integración: mismo id 3 veces | E7: Vigente
A8: 6 | B8: El QR no autoriza nada; /q/:token responde igual válido o inválido | C8: Página pública | D8: Aceptación 18 | E8: Vigente
A9: 7 | B9: CAMBIA (E-01): sin conexión no se opera | C9: App bloquea escaneos y autorizaciones | D9: Manual | E9: Cambiada: ya no hay salida tipo B
A10: 8 | B10: Autorización y salida real son eventos distintos; cambiar el manifiesto invalida la autorización | C10: autorizacion_salida.vigente_key | D10: Integración: invalidación | E10: Vigente
A11: 9 | B11: Los bultos que continúan a bordo no cambian de estado en paradas intermedias | C11: Dominio (escaneo.ts) | D11: Unitaria + E2E | E11: Vigente
A12: 10 | B12: Una encomienda figura disponible solo si TODOS sus bultos lo están | C12: Vista v_encomienda_estado | D12: Probada en MariaDB + E2E | E12: Vigente
A13: 11 | B13: Si WhatsApp falla, la operación continúa | C13: Cola `notificacion` desacoplada | D13: Adaptador que falla a propósito | E13: Vigente
A14: 12 | B14: Sin datos personales en el QR ni en el código legible; el código legible no es secuencial | C14: Generación aleatoria | D14: Unitaria de códigos | E14: Vigente
... A16: 14 | B16: NUEVA: con Evolution los mensajes solo se envían a los números de MENSAJES_NUMEROS_PERMITIDOS | C16: Cola de mensajes | D16: Integración | E16: Propuesta (evita enviar mensajes reales por accidente)

Sheet Pantallas
A1: Pantallas del MVP (9 de la v5.1 + las 3 de apoyo: mensajes, línea de tiempo, QR público)
A2: # | B2: Pantalla | C2: Ruta | D2: Quién | E2: Qué hace | F2: Endpoints | G2: Etapa
A3: 1 | B3: Login | C3: /login | D3: Todos | E3: Correo y contraseña. Cookie de sesión | F3: POST /api/auth/login | G3: E2
A4: 2 | B4: Nueva encomienda | C4: /encomiendas/nueva | D4: Operador | E4: Datos de remitente/destinatario, bultos (peso y medidas), cotización con banner TARIFAS DE DEMOSTRACIÓN, etiquetas QR + código XXXX-XXXX + destino grande | F4: POST /api/encomiendas · POST /api/cotizaciones/calcular | G4: E2
A5: 3 | B5: Viaje y manifiesto | C5: /viajes · /viajes/[id] | D5: Operador | E5: Crear viaje, agregar bultos con su parada de subida y bajada, cerrar. Vista por parada: bajan / suben / continúan. Modificar con motivo | F5: POST /api/viajes · …/manifiesto/items · …/cerrar · …/modificar | G5: E2
A6: 4 | B6: Escaneo | C6: /viajes/[id]/paradas/[p]/escaneo | D6: Ayudante | E6: Cámara continua + campo de código. Resultado en verde/rojo/amarillo grande + texto. Conteo de 'continúan' | F6: POST /api/escaneos | G6: E2
A7: 5 | B7: Salida | C7: /viajes/[id]/paradas/[p]/salida | D7: Supervisor | E7: Autorizar (muestra los bultos que bloquean), Excepción A (motivo + solicitante), Registrar salida real | F7: POST …/autorizar · …/salida-real | G7: E3
A8: 6 | B8: Recepción en agencia | C8: /recepcion | D8: Operador | E8: Escanear bulto por bulto lo que llegó. Muestra a dónde sigue | F8: POST /api/recepciones | G8: E3
A9: 7 | B9: Redespachos | C9: /redespachos | D9: Operador / Supervisor | E9: Lista con plazo; en rojo si venció. Asignar a un viaje | F9: GET /api/redespachos · POST …/asignar | G9: E3
A10: 8 | B10: Entrega | C10: /entrega | D10: Operador | E10: Buscar encomienda, código de 6 dígitos o documento. Parcial con supervisor y motivo. Muestra intentos restantes | F10: GET /api/entregas/buscar · POST /api/entregas | G10: E4
A11: 9 | B11: Panel | C11: /panel | D11: Todos (según rol) | E11: 4–5 tarjetas por rol: por recibir, por cargar, redespachos, disponibles, incidencias. Gerente: solo lectura | F11: GET /api/panel | G11: E4
A12: 10 | B12: Mensajes enviados | C12: /mensajes | D12: Supervisor / Gerente | E12: Lista de mensajes de la cola con estado y destinatario (en modo simulado se ve el texto completo) | F12: GET /api/mensajes | G12: E4
A13: 11 | B13: Línea de tiempo del bulto | C13: /bultos/[id] | D13: Todos | E13: Todos los eventos del bulto en orden: quién, cuándo, qué. Es lo más vistoso de la demo | F13: GET /api/bultos/[id]/timeline | G13: E4
A14: 12 | B14: QR público | C14: /q/[token] | D14: Cualquiera (sin sesión) | E14: Respuesta idéntica, sin datos, para token válido o inválido | F14: — | G14: E2

Sheet API
A1: Endpoints (Next.js route handlers; todos validan con Zod)
A2: Método | B2: Ruta | C2: Rol | D2: Nota
A3: POST | B3: /api/auth/login · /api/auth/logout · GET /api/auth/me | C3: Todos | D3: Cookie HttpOnly; Secure; SameSite=Lax
A4: POST | B4: /api/encomiendas | C4: operador | D4: Crea encomienda + bultos + cotización + etiquetas en UNA transacción; encola aviso 'registro'
A5: GET | B5: /api/encomiendas · /api/encomiendas/[id] | C5: según agencia | D5: Filtro por agencia SIEMPRE en el servidor
A6: POST | B6: /api/cotizaciones/calcular | C6: operador | D6: Función pura; devuelve detalle o sinRegla
A7: POST | B7: /api/viajes | C7: operador | D7: Crea viaje
A8: POST | B8: /api/viajes/[id]/manifiesto/items | C8: operador | D8: Valida estado, tramo y paradas con agencia
A9: POST | B9: /api/viajes/[id]/manifiesto/cerrar | C9: operador | D9: Bultos → pendiente_despacho, fija viaje_actual_id
A10: POST | B10: /api/viajes/[id]/manifiesto/modificar | C10: operador | D10: Motivo obligatorio; nueva versión; invalida autorización
A11: GET | B11: /api/viajes/[id]/paradas/[p] | C11: ayudante, operador, supervisor | D11: Listas bajan/suben/continúan + estado de conciliación
A12: POST | B12: /api/escaneos | C12: ayudante, operador | D12: Idempotente por eventId
A13: POST | B13: /api/viajes/[id]/paradas/[p]/autorizar | C13: supervisor | D13: Normal o excepción A
... A15: POST | B15: /api/recepciones | C15: operador | D15: Escaneo bulto por bulto; crea redespacho o deja disponible; emite código y aviso
A16: GET | B16: /api/redespachos | C16: operador, supervisor
A17: POST | B17: /api/redespachos/[id]/asignar | C17: operador, supervisor
A18: GET | B18: /api/entregas/buscar?q= | C18: operador | D18: Busca por codigo de encomienda o de un bulto
A19: POST | B19: /api/entregas | C19: operador | D19: Verifica el codigo (intento atomico) y entrega; parcial exige supervisor (usuario+contrasena) y motivo
A20: POST | B20: /api/incidencias · /api/incidencias/[id]/resolver | C20: operador / supervisor | D20: Resolver = evento vinculado
A21: GET | B21: /api/panel | C21: según rol | D21: Consultas, no tablas nuevas
A22: GET | B22: /api/bultos/[id]/timeline | C22: todos | D22: Eventos del bulto
A23: GET | B23: /api/mensajes | C23: supervisor, gerente
A24: GET | B24: /api/export/eventos.csv | C24: supervisor, gerente | D24: Un solo CSV (E-09)
A25: POST | B25: /api/cron/mensajes | C25: cron (clave CRON_SECRET) | D25: Procesa la cola de WhatsApp; llamado cada minuto desde cPanel
A26: GET | B26: /q/[token] | C26: público | D26: Respuesta idéntica en forma, tiempo y código HTTP
A27: — | B27: FUERA del MVP: /sync · /eventos/[id]/corregir · /ajustes · /webhooks/whatsapp | C27: — | D27: E-01, E-10

Sheet Mensajes WhatsApp
A1: Avisos por WhatsApp (Evolution API)
A2: Los textos son ejemplos para la demo: Cheche decide el tono final. 'Última información registrada' en lugar de ubicación en vivo (la v5 prohíbe mostrar posición en tiempo real).
A3: Plantilla | B3: Cuándo | C3: A quién | D3: Texto de ejemplo | E3: Variables | F3: ¿MVP?
A4: registro_confirmado | B4: Al registrar la encomienda | C4: Destinatario | D4: Hola {nombre}, la cooperativa Unión Transportes Cariamanga registró una encomienda para ti de parte de {remitente}: {n} bulto(s) con destino {agencia_destino}. Te avisaremos cada avance. | E4: nombre, remitente, n, agencia_destino | F4: Sí
A5: en_camino | B5: Al registrar la salida real desde el origen | C5: Destinatario | D5: Tu encomienda ({n} bultos) salió de {agencia_origen} rumbo a {agencia_destino}. Última información registrada: {fecha_hora}. | E5: n, agencia_origen, agencia_destino, fecha_hora | F5: Sí (E-14)
A6: llegada_intermedia | B6: Al recibir bultos en una agencia que NO es el destino final | C6: Destinatario | D6: Tu encomienda llegó a {agencia} ({recibidos} de {total} bultos) y continúa su camino hacia {agencia_destino}. Última información registrada: {fecha_hora}. | E6: agencia, recibidos, total, agencia_destino, fecha_hora | F6: Sí (E-14)
A7: disponible_retiro | B7: Cuando TODOS los bultos están en la agencia destino | C7: Destinatario | D7: Tu encomienda está lista para retirar en {agencia}. Tu código de retiro es {codigo} y vale hasta el {fecha}. Preséntalo con un documento de identidad. | E7: agencia, codigo, fecha | F7: Sí
A8: recordatorio_retiro | B8: Si no retira en N días | C8: Destinatario | D8: Recordatorio: tu encomienda sigue esperando en {agencia}. | E8: agencia | F8: No (E-07)
A9: Reglas de la cola
A10: Deduplicación | B10: dedupe_key único: enc:{id}:{plantilla}:{tel}. Reintentar no duplica
A11: Reintentos | B11: Hasta 8 intentos con espera creciente (1, 5, 15 min…). Si agota → estado 'fallida' y se ve en el panel; la operación NO se detiene
A12: Tope | B12: parámetro mensajes.max_por_encomienda (5 en la demo; era 3 en la v5)
A13: Código de retiro en el texto | B13: Se guarda en `cuerpo` hasta enviarse y luego se redacta con ••••••. En BD queda solo el HMAC
A14: Modo prueba | B14: Con proveedor evolution solo se envia a los numeros de MENSAJES_NUMEROS_PERMITIDOS (.env). Los demas quedan 'descartada'
A15: Llamada a Evolution
A16: Petición | B16: POST {EVOLUTION_URL}/message/sendText/{EVOLUTION_INSTANCE} con cabecera `apikey`. Cuerpo: número internacional sin + y texto | F16: VERIFICAR
A17: Nota de versión | B17: El nombre de los campos del cuerpo cambia entre Evolution v1 y v2. Lo ajusto contra la documentación de TU versión cuando me la digas; no lo doy por seguro
A18: Si falla | B18: Se guarda ultimo_error y se reintenta. Nunca se bloquea el escaneo, la recepción ni la entrega

Sheet Parametros
A1: Parámetros (tabla `parametro`) y variables de entorno
A2: Los valores 'defecto' son míos para poder construir; NO son datos de la cooperativa.
A3: Clave | B3: Valor en la demo | C3: Qué es | D3: Estado
A4: redespacho.plazo_horas | B4: 1 | C4: Plazo para redespachar (corto para mostrar el vencimiento en la demo) | D4: Demo (producción: 12, por confirmar)
A5: codigo_retiro.caducidad_dias | B5: 7 | C5: Vigencia del código de retiro | D5: Por confirmar
A6: codigo_retiro.max_intentos | B6: 5 | C6: Intentos antes de bloquear | D6: Defecto
A7: busqueda_manual.max_por_minuto | B7: 10 | C7: Límite de búsquedas por código legible por usuario | D7: Defecto
A8: descuento.umbral_supervisor_pct | B8: 5 | C8: Descuento sobre el cual hace falta supervisor (los ajustes están fuera del MVP) | D8: Por confirmar
A9: exigir_reescaneo_continuan | B9: false | C9: Si es true, los que continúan se re-escanean en vez de contarse | D9: Defecto
A10: exigir_escaneo_recepcion | B10: true | C10: La recepción exige escanear cada bulto | D10: Decide el piloto
A11: mensajes.max_por_encomienda | B11: 5 | C11: Tope de avisos por encomienda (v5: 3) | D11: Propuesta E-14
A12: MENSAJES_PROVEEDOR (.env) | B12: simulado | C12: 'simulado' o 'evolution' | D12: Implementado
A13: MENSAJES_NUMEROS_PERMITIDOS (.env) | B13: (vacio) | C13: Con evolution solo se envia a estos numeros (5939XXXXXXXX, separados por coma); el resto queda descartada | D13: Implementado
A14: Variables de entorno (.env) — NO van en la BD ni en el repositorio
A15: DATABASE_HOST / PORT / NAME / USER / PASSWORD | B15: — | C15: Conexión a MySQL/MariaDB | D15: Tú
A16: SESSION_SECRET | B16: (aleatorio largo) | C16: Firma de cookies | D16: Se genera
A17: RETIRO_HMAC_SECRET | B17: (aleatorio largo) | C17: Secreto del HMAC del código de retiro | D17: Se genera
A18: EVOLUTION_URL · EVOLUTION_INSTANCE · EVOLUTION_API_KEY | B18: — | C18: Conexión a Evolution | D18: Tú
A19: CRON_SECRET | B19: (aleatorio largo) | C19: Clave que debe traer el cron de cPanel | D19: Se genera
A20: TZ_DISPLAY | B20: America/Guayaquil | C20: Zona horaria para mostrar fechas | D20: Fijo

Sheet Plan
A1: Plan de trabajo (checklist vivo)
A2: Cambia el Estado con la lista desplegable. El avance de la hoja LEEME se calcula solo. 'Hecho' = codigo escrito Y probado (unitarias, integracion en MariaDB y/o HTTP). 'En curso' = codigo listo pero falta verlo en un navegador / con Evolution real. Pendiente = depende de ti (cPanel, cron, despliegue).
A3: ID | B3: Etapa | C3: Tarea | D3: Listo cuando… | E3: Depende de | F3: Estado | G3: Quién
A4: 0.1 | B4: E0 | C4: Spec v5 + enmiendas v5.1 integradas en el proyecto | D4: Documentos en /docs | F4: Hecho | G4: Abel + Claude
A5: 0.2 | B5: E0 | C5: Crear proyecto Next.js + TypeScript estricto + Vitest + Git | D5: `npm run dev` y `npm test` corren | F5: Hecho | G5: Claude
A6: 0.3 | B6: E0 | C6: domain/estados.ts | D6: Transiciones del §5.1 de la v5 | E6: 0.2 | F6: Hecho | G6: Claude
A7: 0.4 | B7: E0 | C7: domain/escaneo.ts | D7: Decide carga/descarga sin tocar BD | E7: 0.3 | F7: Hecho | G7: Claude
A8: 0.5 | B8: E0 | C8: domain/salida.ts (sin rama offline) | D8: Concilia por identidad; quitar tipo B | E8: 0.3 | F8: Hecho | G8: Claude
A9: 0.6 | B9: E0 | C9: domain/tarifa.ts y domain/codigos.ts | D9: Tarifa por rangos; QR/códigos aleatorios | E9: 0.2 | F9: Hecho | G9: Claude
A10: 0.7 | B10: E0 | C10: Pruebas unitarias v5 §10.1 en verde (adaptadas a E-01) | D10: TODAS pasan. Es la primera comprobación real del código de referencia | E10: 0.3–0.6 | F10: Hecho | G10: Claude + Abel
A11: 1.1 | B11: E1 | C11: Esquema MySQL/MariaDB (001_init_mvp.sql) escrito y probado en MariaDB 10.11 | D11: Triggers, unicidad vigente, vista, intentos atómicos probados | F11: Hecho | G11: Claude
A12: 1.2 | B12: E1 | C12: seed.sql con datos de demostración | D12: 3 agencias, ruta, 4 usuarios, tarifas demo | E12: 1.1 | F12: Hecho | G12: Claude
A13: 1.3 | B13: E1 | C13: Verificar versión y TRIGGERS en tu cPanel (hoja 'Necesito de ti' #1 y #2) | D13: Un trigger de prueba se crea sin error 1419 | F13: Pendiente | G13: Abel
A14: 1.4 | B14: E1 | C14: Aplicar 001_init_mvp.sql y seed.sql en tu BD | D14: 25 tablas creadas | E14: 1.3 | F14: Pendiente | G14: Abel
A15: 1.5 | B15: E1 | C15: Capa de BD: pool mysql2, transacciones, funciones auxiliares (param, ErrorNegocio, exigirRol…) | D15: Pruebas de integración conectan a MySQL real | E15: 1.4 | F15: Hecho | G15: Claude
A16: 1.6 | B16: E1 | C16: Pruebas de integración de BD: trigger, vigente_key, código único | D16: UPDATE/DELETE de evento fallan; 2ª autorización vigente falla | E16: 1.5 | F16: Hecho | G16: Claude
A17: 1.7 | B17: E1 | C17: scripts/seed-usuarios.ts (argon2id) | D17: Los 4 usuarios pueden entrar | E17: 1.5 | F17: Hecho | G17: Claude
A18: 2.1 | B18: E2 | C18: Login, sesión, cookie y permisos por rol y agencia | D18: Un usuario sin permiso recibe 403 | E18: 1.7 | F18: Hecho | G18: Claude
A19: 2.2 | B19: E2 | C19: Nueva encomienda: bultos, QR, código legible, cotización con tabla | D19: Una transacción; sin regla → no se inventa precio | E19: 2.1, 0.6 | F19: Hecho | G19: Claude
A20: 2.3 | B20: E2 | C20: Etiquetas imprimibles (QR + XXXX-XXXX + destino grande) | D20: Se imprime desde el navegador | E20: 2.2 | F20: En curso | G20: Claude
A21: 2.4 | B21: E2 | C21: Viaje + manifiesto borrador + cerrar | D21: Bultos pasan a pendiente_despacho al cerrar | E21: 2.2 | F21: Hecho | G21: Claude
A22: 2.5 | B22: E2 | C22: Modificar manifiesto con motivo (nueva versión, invalida autorización) | D22: Criterio 5 | E22: 2.4 | F22: Hecho | G22: Claude
A23: 2.6 | B23: E2 | C23: Escaneo idempotente (carga y descarga) + pantalla de escaneo | D23: Mismo eventId 3 veces = 1 evento | E23: 2.4, 0.4 | F23: Hecho | G23: Claude
A24: 2.7 | B24: E2 | C24: Página pública /q/[token] indistinguible | D24: Criterio 18 | E24: 2.1 | F24: Hecho | G24: Claude
A25: 3.1 | B25: E3 | C25: Autorizar salida (conciliación) y excepción A | D25: Criterios 3, 4, 22 | E25: 2.6, 0.5 | F25: Hecho | G25: Claude
... A39: 5.1 | B39: Despliegue | C39: Publicar la demo (opción A, B o C) | D39: Acceso con HTTPS desde un celular | E39: 4.8 | F39: Pendiente | G39: Abel

Sheet Guion demo
A1: Guion de la demo = prueba E2E principal
A2: Se ensaya con `reset-demo.ts` para empezar desde cero cada vez.
A3: Paso | B3: Quién | C3: Acción | D3: Resultado esperado | E3: Pantalla | F3: Criterios
A4: 1 | B4: Operador | C4: Registra encomienda de 3 bultos Quito → Zumba | D4: Cotizacion con banner DEMO; 3 etiquetas; mensaje 'registro' en la cola | E4: Nueva encomienda | F4: 10
A5: 2 | B5: Operador | C5: Crea viaje y arma manifiesto: A baja en Loja; B y C bajan en Zumba. Cierra | D5: Bultos en pendiente_despacho; manifiesto v1 cerrado | E5: Viaje y manifiesto | F5: 5
A6: 3 | B6: Ayudante | C6: Parada 1: escanea carga de A y B | D6: Verde; A y B cargados | E6: Escaneo | F6: 1
A7: 4 | B7: Ayudante | C7: Escanea un bulto AJENO | D7: Rojo; rechazo + incidencia 'sobrante' | E7: Escaneo | F7: 1
A8: 5 | B8: Ayudante | C8: Escanea A otra vez | D8: Aviso 'repetido'; no suma | E8: Escaneo | F8: 2
A9: 6 | B9: Supervisor | C9: Intenta autorizar la salida (falta C y hay una incidencia sin resolver) | D9: BLOQUEADO; lista que falta; la incidencia no se puede saltar con excepcion | E9: Salida | F9: 3, 22
A10: 7 | B10: Supervisor / Ayudante | C10: Resuelve la incidencia; el ayudante carga C | D10: Se puede autorizar | E10: Salida · Escaneo | F10: —
A11: 8 | B11: Supervisor | C11: Autoriza y registra salida real | D11: Bultos en_transito; mensaje 'en camino' en la cola | E11: Salida | F11: —
A12: 9 | B12: Ayudante | C12: En Loja (parada 2): descarga A | D12: Verde; A descargado | E12: Escaneo | F12: —
A13: 10 | B13: Ayudante | C13: En Loja: intenta bajar B | D13: ALERTA roja 'no lo baje: continua'; sin cambio de estado; abre incidencia | E13: Escaneo | F13: 21
A14: 11 | B14: Ayudante | C14: Registra el conteo de los que continuan: 2 | D14: Conteo coincide con lo esperado | E14: Escaneo | F14: 22
A15: 12 | B15: Supervisor | C15: Resuelve la incidencia de la alerta, autoriza y registra salida de Loja | D15: Bus sigue a Zumba; B y C siguen en_transito | E15: Salida | F15: —
... A21: 18 | B21: Todos | C21: Abren la linea de tiempo del bulto desde el Panel | D21: Todos los eventos: quien, cuando, que | E21: Linea de tiempo | F21: —

Sheet Aceptación
A1: Criterios de aceptación (v5 §11 filtrados por la v5.1)
A2: # | B2: Criterio | C2: ¿Entra en el MVP? | D2: Cómo se prueba | E2: Estado
A3: 1 | B3: Paquete ajeno genera rechazo o incidencia | C3: Sí | D3: Unitaria escaneo | E3: Cumplido
A4: 2 | B4: Escaneo repetido no suma | C4: Sí | D4: Unitaria + integración | E4: Cumplido
A5: 3 | B5: Faltante bloquea la autorización normal | C5: Sí | D5: Unitaria salida | E5: Cumplido
A6: 4 | B6: Excepción exige permisos y motivo | C6: Sí | D6: Endpoint autorizar | E6: Cumplido
A7: 5 | B7: Cambio de manifiesto obliga a reevaluar | C7: Sí | D7: Integración | E7: Cumplido
A8: 6 | B8: Descarga incorrecta no cambia el destino | C8: Sí | D8: Unitaria escaneo | E8: Cumplido
A9: 7 | B9: Redespacho pendiente permanece visible | C9: Simplificado (panel, sin job) | D9: Vista del panel | E9: Pendiente
A10: 8 | B10: Encomienda incompleta no figura disponible | C10: Sí | D10: Vista v_encomienda_estado (ya probada) | E10: Cumplido
A11: 9 | B11: Entrega exige verificación acordada | C11: Sí | D11: Servicio entregar | E11: Cumplido
A12: 10 | B12: Reintento no duplica eventos ni mensajes | C12: Sí | D12: Integración + dedupe_key | E12: Cumplido
A13: 11 | B13: Sin acceso fuera de permisos | C13: Simplificado (sin RLS) | D13: Usuario de otra agencia → 403/404 | E13: Pendiente
A14: 12 | B14: Respaldo restaurable | C14: No (E-10) | D14: — | E14: Fuera del MVP
... A24: 22 | B24: Salida intermedia exige conciliar o excepción | C24: Sí | D24: Unitaria salida | E24: Cumplido

Sheet Riesgos
A1: Riesgos conocidos
A2: # | B2: Riesgo | C2: Impacto | D2: Probabilidad | E2: Qué hacemos | F2: Cuándo mirarlo
A3: 1 | B3: Tu cPanel no permite crear TRIGGERS (error 1419 / SUPER). Sin ellos, 'eventos inmutables' dependería solo del código | C3: Alto | D3: Media | E3: Probarlo el día 1 (hoja 'Necesito de ti' #2). Si falla: (a) BD en un VPS o servidor propio, (b) pedir al hosting el permiso, (c) respaldo propuesto: cada evento guarda el hash del anterior (cadena) para detectar manipulación | F3: Antes de E1
A4: 2 | B4: Next.js dentro del Node.js App de cPanel: poca memoria o versión vieja de Node | C4: Medio | D4: Media | E4: Compilar en tu PC y subir el resultado; si no alcanza, demo desde laptop (opción B) o VPS | F4: Antes del despliegue
A5: 3 | B5: Evolution no es la API oficial: riesgo de que bloqueen el número | C5: Medio | D5: Media | E5: Número dedicado, solo mensajes transaccionales a destinatarios reales, bajo volumen. Opción futura: Cloud API oficial (la interfaz permite cambiar) | F5: E4
A6: 4 | B6: En la demo los mensajes de Evolution son REALES: podría llegar uno a alguien que no sabe | C6: Alto | D6: Media | E6: `mensajes.modo_prueba = true` con lista de números permitidos; todo lo demás se descarta | F6: E4
A7: 5 | B7: Cámara no funciona sin HTTPS | C7: Medio | D7: Alta | E7: Dominio con SSL (AutoSSL de cPanel) o usar localhost; siempre el campo de código manual como respaldo | F7: Antes de la demo
A8: 6 | B8: El código de referencia de la v5 nunca se ejecutó | C8: Medio | D8: Alta | E8: Pruebas del dominio primero (E0); se corrige lo que falle | F8: E0
A9: 7 | B9: SQL probado en MariaDB 10.11; tu cPanel podría ser MySQL 5.7/8 u otra versión de MariaDB | C9: Medio | D9: Media | E9: Dime la versión; ajusto y vuelvo a probar. CHECK requiere MySQL ≥ 8.0.16 o MariaDB ≥ 10.2 | F9: E1
A10: 8 | B10: BD remota (opción B): latencia y puerto abierto a Internet | C10: Medio | D10: Media | E10: Permitir solo tu IP; usar la BD solo para la demo; no meter datos reales | F10: E1
A11: 9 | B11: El cron de cPanel corre como mínimo cada minuto | C11: Bajo | D11: Alta | E11: Aceptable: el aviso llega hasta ~1 min después | F11: E4
A12: 10 | B12: Zona horaria del servidor distinta de Ecuador | C12: Bajo | D12: Alta | E12: Guardar UTC y formatear en America/Guayaquil (E-18) | F12: E2
A13: 11 | B13: Alcance: el MVP crece | C13: Medio | D13: Alta | E13: Todo cambio entra como enmienda numerada y se mueve al plan; lo recortado queda en la hoja Decisiones | F13: Siempre

Sheet Bitácora
A1: Bitácora de avances
A2: Cada vez que avancemos, aquí se anota qué se terminó y qué enmienda nueva (E-19, E-20…) cambia algo.
A3: Fecha | B3: Avance / enmienda | C3: Quién
A4: 2026-10-06 | B4: Se crea v5.1: MVP demo, sin offline (E-01 a E-10) | C4: Abel + Claude
A5: 2026-10-06 | B5: Se define el stack: Next.js + MySQL/MariaDB (cPanel) + Evolution API (E-11 a E-18) | C5: Abel + Claude
A6: 2026-10-06 | B6: 001_init_mvp.sql y seed.sql escritos y validados en MariaDB 10.11 (triggers, unicidad vigente, vista, intentos). Pendiente probar en tu cPanel | C6: Claude
A7: 2026-10-06 | B7: Proyecto Next.js completo: dominio (27 pruebas), 25 tablas, servicios, 31 endpoints, 12 pantallas. 23 pruebas de integracion en MariaDB (guion completo) y 21 chequeos HTTP en verde. Enmiendas E-19 a E-22. NO probado: tu cPanel, MySQL 8, Evolution real, pantallas en navegador | C7: Claude
